Workbook
Name NativeTimeline_Appointment_Date: #N/A
Name Slicer_Clinic: #N/A
Name Slicer_Clinic1: #N/A
Name Slicer_Month: #N/A
Name Slicer_Month1: #N/A
Name Slicer_Payer_Type: #N/A
Name Slicer_Payer_Type1: #N/A
Name Slicer_Therapist: #N/A
Name Slicer_Therapy_Type: #N/A
Name Slicer_Therapy_Type1: #N/A

Sheet Dashboard_Review
AB18: ~

Sheet Dashboard_Final
A1: EXCEL CLINICAL OPS DASHBOARD | OUTPATIENT REHAB OPTIMIZATION | P1: Y-2025
A3: Total Revenue Generated | F3: Overall No-Show Rate | K3: Avg Therapist Utilization | P3: Total Lost Revenue
A7: =GETPIVOTDATA("Total Revenue Generated",Pivot_Data!$A$5) -> 1990900 | F7: =GETPIVOTDATA("Overall No-Show Rate",Pivot_Data!$A$5) -> 0.151 | K7: =Pivot_Data!D6 -> 0.6249501 | P7: =GETPIVOTDATA("Total Lost Revenue",Pivot_Data!$A$5) -> 543350
A10: from Completed Sessions | F10: Goal <10% | K10: Target: 85% | P10: from Missed Appointments
E16: NO-SHOW RATE BY DAY OF WEEK | K16: THERAPIST UTILIZATION vs TARGET 85%
E19: Monday | H19: =INDEX(Pivot_Data!$A$36:$D$43,MATCH(Dashboard_Final!E19,Pivot_Data!$A$36:$A$43,0),4) -> 0.19085487
E21: Tuesday | H21: =INDEX(Pivot_Data!$A$36:$D$43,MATCH(Dashboard_Final!E21,Pivot_Data!$A$36:$A$43,0),4) -> 0.1433121
E23: Wednesday | H23: =INDEX(Pivot_Data!$A$36:$D$43,MATCH(Dashboard_Final!E23,Pivot_Data!$A$36:$A$43,0),4) -> 0.14576271
E25: Thursday | H25: =INDEX(Pivot_Data!$A$36:$D$43,MATCH(Dashboard_Final!E25,Pivot_Data!$A$36:$A$43,0),4) -> 0.11481481
E27: Friday | H27: =INDEX(Pivot_Data!$A$36:$D$43,MATCH(Dashboard_Final!E27,Pivot_Data!$A$36:$A$43,0),4) -> 0.11184211
E29: Saturday | H29: =INDEX(Pivot_Data!$A$36:$D$43,MATCH(Dashboard_Final!E29,Pivot_Data!$A$36:$A$43,0),4) -> 0.18021201
E31: Sunday | H31: =INDEX(Pivot_Data!$A$36:$D$43,MATCH(Dashboard_Final!E31,Pivot_Data!$A$36:$A$43,0),4) -> 0.064516129
E36: THERAPIST DETAILS | K36: APPOINTMENT VOLUME TREND
E39: Therapist | H39: Lakshmi Pillai
E40: Utilization % | H40: =_xlfn.IFNA(INDEX(Pivot_Data!$A$12:$G$27,MATCH($H$39,Pivot_Data!$A$12:$A$27,0),7),"") -> 0.66237377
E41: Total Appointments | H41: =_xlfn.IFNA(INDEX(Pivot_Data!$A$12:$G$27,MATCH($H$39,Pivot_Data!$A$12:$A$27,0),2),"") -> 160
E42: No-show count | H42: =_xlfn.IFNA(INDEX(Pivot_Data!$A$12:$G$27,MATCH($H$39,Pivot_Data!$A$12:$A$27,0),3),"") -> 18
E43: Revenue Generated (INR) | H43: =_xlfn.IFNA(INDEX(Pivot_Data!$A$12:$G$27,MATCH($H$39,Pivot_Data!$A$12:$A$27,0),4),"") -> 180050
E56: VOLUME & STATUS BREAKDOWN BY CLINICAL SPECIALITY / THERAPY
E80: REVENUE CLINIC x THERAPY
E112: NO-SHOW RECOVERY PIPELINE MATRIX
E114: Target No-Show Reduction Goal | I114: Total No-Shows | L114: Saved Appointments | O114: Avg Session Fee | R114: Recovered Revenue Pipeline
E115: 0.02 | I115: {=SUMPRODUCT((SUBTOTAL(103,OFFSET(INDEX(Appointments_Tbl[Appointment_ID],1),ROW(Appointments_Tbl[Appointment_ID])-ROW(INDEX(Appointments_Tbl[Appointment_ID],1)),0,1)))*(Appointments_Tbl[No_Show_Flag]))} -> 302 | L115: =I115*E115 -> 6.04 | O115: {=IFERROR(SUMPRODUCT((SUBTOTAL(103,OFFSET(INDEX(Appointments_Tbl[Appointment_ID],1),ROW(Appointments_Tbl[Appointment_ID])-ROW(INDEX(Appointments_Tbl[Appointment_ID],1)),0,1)))*(Appointments_Tbl[No_Show_Flag])*(Appointments_Tbl[Session_Fee_INR]))/I115,0)} -> 1334.4371 | R115: =O115*L115 -> 8060
E118: Formula: Saved Appointments = Total No-Shows × Reduction Goal. Recovered Revenue Pipeline = Saved Appointments × Average Session Fee for visible no-show appointments.

Sheet Pivot_Data
A5: Total Revenue Generated | B5: Overall No-Show Rate | C5: Total Lost Revenue | D5: Avg Therapist Utilization
A6: 1990900 | B6: 0.151 | C6: 543350 | D6: =SUMIF(Appointments_Tbl[Appointment_Status],"Completed",Appointments_Tbl[Treated_Minutes])/SUM(Appointments_Tbl[Allocated_Shift_Capacity_Minutes]) -> 0.6249501
A9: Clinic | B9: (All)
A10: Month | B10: (All)
A12: Therapist | B12: Total Appointments | C12: No-Show Count | D12: Revenue Generated | E12: Treated Minutes | F12: Allocated Minutes | G12: Utilization % | J12: Therapist | K12: Utilization% | L12: Target 85%
A13: Anjali Menon | B13: 121 | C13: 24 | D13: 103400 | E13: 4800 | F13: 7793 | G13: =IF(F13=0,0,E13/F13) -> 0.61593738 | J13: {=OFFSET(A12,1,0,COUNTA(A12:A31)-2,1)} -> Anjali Menon | K13: =IF(J13="","",INDEX(A12:G28,MATCH(J13,A12:A28,0),7)) -> 0.61593738 | L13: 0.85
A14: Aparna Varma | B14: 132 | C14: 11 | D14: 141400 | E14: 6120 | F14: 9180.9 | G14: =IF(F14=0,0,E14/F14) -> 0.66660131 | J14: Aparna Varma | K14: =IF(J14="","",INDEX(A13:G29,MATCH(J14,A13:A29,0),7)) -> 0.66660131 | L14: 0.85
A15: Arun Raj | B15: 123 | C15: 17 | D15: 120900 | E15: 5160 | F15: 8499.9 | G15: =IF(F15=0,0,E15/F15) -> 0.60706597 | J15: Arun Raj | K15: =IF(J15="","",INDEX(A14:G30,MATCH(J15,A14:A30,0),7)) -> 0.60706597 | L15: 0.85
A16: Deepa Krishnan | B16: 126 | C16: 32 | D16: 101550 | E16: 4800 | F16: 8668.2 | G16: =IF(F16=0,0,E16/F16) -> 0.55374818 | J16: Deepa Krishnan | K16: =IF(J16="","",INDEX(A15:G31,MATCH(J16,A15:A31,0),7)) -> 0.55374818 | L16: 0.85
A17: Divya Nambiar | B17: 135 | C17: 19 | D17: 146550 | E17: 5715 | F17: 8826.8 | G17: =IF(F17=0,0,E17/F17) -> 0.64746001 | J17: Divya Nambiar | K17: =IF(J17="","",INDEX(A16:G32,MATCH(J17,A16:A32,0),7)) -> 0.64746001 | L17: 0.85
A18: Fathima Rahman | B18: 134 | C18: 15 | D18: 149000 | E18: 5820 | F18: 8988.9 | G18: =IF(F18=0,0,E18/F18) -> 0.64746521 | J18: Fathima Rahman | K18: =IF(J18="","",INDEX(A17:G33,MATCH(J18,A17:A33,0),7)) -> 0.64746521 | L18: 0.85
A19: Joel Thomas | B19: 133 | C19: 15 | D19: 151600 | E19: 5940 | F19: 8974.6 | G19: =IF(F19=0,0,E19/F19) -> 0.66186794 | J19: Joel Thomas | K19: =IF(J19="","",INDEX(A18:G34,MATCH(J19,A18:A34,0),7)) -> 0.66186794 | L19: 0.85
A20: Lakshmi Pillai | B20: 160 | C20: 18 | D20: 180050 | E20: 7005 | F20: 10575.6 | G20: =IF(F20=0,0,E20/F20) -> 0.66237377 | J20: Lakshmi Pillai | K20: =IF(J20="","",INDEX(A19:G35,MATCH(J20,A19:A35,0),7)) -> 0.66237377 | L20: 0.85
A21: Meera S | B21: 127 | C21: 24 | D21: 105800 | E21: 4935 | F21: 8448.7 | G21: =IF(F21=0,0,E21/F21) -> 0.58411353 | J21: Meera S | K21: =IF(J21="","",INDEX(A20:G36,MATCH(J21,A20:A36,0),7)) -> 0.58411353 | L21: 0.85
A22: Nisha Thomas | B22: 152 | C22: 22 | D22: 155850 | E22: 6705 | F22: 10675.1 | G22: =IF(F22=0,0,E22/F22) -> 0.62809716 | J22: Nisha Thomas | K22: =IF(J22="","",INDEX(A21:G37,MATCH(J22,A21:A37,0),7)) -> 0.62809716 | L22: 0.85
A23: Priya Mathew | B23: 129 | C23: 18 | D23: 127600 | E23: 5505 | F23: 8898.3 | G23: =IF(F23=0,0,E23/F23) -> 0.6186575 | J23: Priya Mathew | K23: =IF(J23="","",INDEX(A22:G38,MATCH(J23,A22:A38,0),7)) -> 0.6186575 | L23: 0.85
A24: Rahul P | B24: 118 | C24: 19 | D24: 108600 | E24: 5115 | F24: 8088.6 | G24: =IF(F24=0,0,E24/F24) -> 0.63237149 | J24: Rahul P | K24: =IF(J24="","",INDEX(A23:G39,MATCH(J24,A23:A39,0),7)) -> 0.63237149 | L24: 0.85
A25: Rohit George | B25: 139 | C25: 18 | D25: 152450 | E25: 6000 | F25: 9360.2 | G25: =IF(F25=0,0,E25/F25) -> 0.64101194 | J25: Rohit George | K25: =IF(J25="","",INDEX(A24:G40,MATCH(J25,A24:A40,0),7)) -> 0.64101194 | L25: 0.85
... A27: Vishnu Nair | B27: 128 | C27: 20 | D27: 111900 | E27: 5175 | F27: 8439.2 | G27: =IF(F27=0,0,E27/F27) -> 0.61320978 | J27: Vishnu Nair | K27: =IF(J27="","",INDEX(A26:G42,MATCH(J27,A26:A42,0),7)) -> 0.61320978 | L27: 0.85
A28: Grand Total | B28: 2000 | C28: 302 | D28: 1990900 | E28: 84540 | F28: 135274.8 | G28: =IF(F28=0,0,E28/F28) -> 0.6249501
A33: Clinic | B33: (All)
A34: Month | B34: (All)
A36: Day_of_Week | B36: No-Show Count | C36: Total Appointments | D36: No-Show Rate | F36: Day of Week | G36: No Show rate
A37: Sunday | B37: 2 | C37: 31 | D37: =IF(C37=0,0,B37/C37) -> 0.064516129 | F37: Monday | G37: {=INDEX($A$37:$D$43,MATCH($A$37:$A$43,$A$37:$A$43,0),4)} -> 0.064516129
A38: Monday | B38: 96 | C38: 503 | D38: =IF(C38=0,0,B38/C38) -> 0.19085487 | F38: Tuesday | G38: 0.19085487
A39: Tuesday | B39: 45 | C39: 314 | D39: =IF(C39=0,0,B39/C39) -> 0.1433121 | F39: Wednesday | G39: 0.1433121
A40: Wednesday | B40: 43 | C40: 295 | D40: =IF(C40=0,0,B40/C40) -> 0.14576271 | F40: Thursday | G40: 0.14576271
A41: Thursday | B41: 31 | C41: 270 | D41: =IF(C41=0,0,B41/C41) -> 0.11481481 | F41: Friday | G41: 0.11481481
A42: Friday | B42: 34 | C42: 304 | D42: =IF(C42=0,0,B42/C42) -> 0.11184211 | F42: Saturday | G42: 0.11184211
A43: Saturday | B43: 51 | C43: 283 | D43: =IF(C43=0,0,B43/C43) -> 0.18021201 | F43: Sunday | G43: 0.18021201
A44: Grand Total | B44: 302 | C44: 2000 | D44: =IF(C44=0,0,B44/C44) -> 0.151
A47: Clinic | B47: (All)
A48: Month | B48: (All)
A50: Count | B50: Appointment_Status
A51: Therapy_Type | B51: Cancelled Late | C51: Completed | D51: No-show | E51: Rescheduled | F51: Grand Total
A52: Electrotherapy | B52: 15 | C52: 248 | D52: 40 | E52: 10 | F52: 313
A53: Exercise Therapy | B53: 17 | C53: 248 | D53: 56 | E53: 10 | F53: 331
A54: Manual Therapy | B54: 18 | C54: 255 | D54: 56 | E54: 18 | F54: 347
A55: Neuro Rehab | B55: 17 | C55: 278 | D55: 48 | E55: 8 | F55: 351
A56: Posture Correction | B56: 21 | C56: 252 | D56: 53 | E56: 11 | F56: 337
...

Sheet Appointments
A1: Appointment_ID | B1: Appointment_Date | C1: Month | D1: Day_of_Week | E1: Time_Slot | F1: Clinic | G1: District | H1: Therapist | I1: Patient_ID | J1: Patient_Type | K1: Therapy_Type | L1: Payer_Type | M1: Referral_Source | N1: Appointment_Status | O1: Scheduled_Minutes | P1: Treated_Minutes | Q1: Allocated_Shift_Capacity_Minutes | R1: Session_Fee_INR | S1: Revenue_INR | T1: Lost_Revenue_INR | U1: No_Show_Flag | V1: Completed_Flag | W1: Cancellation_Flag | X1: Utilization_Target
A2: APT-00001 | B2: 46014 | C2: Dec | D2: Tuesday | E2: Evening | F2: Palakkad Rehab Clinic | G2: Palakkad | H2: Meera S | I2: PT-1019 | J2: Chronic Pain | K2: Posture Correction | L2: Self Pay | M2: Corporate Wellness | N2: Completed | O2: 90 | P2: 90 | Q2: 118.8 | R2: 1900 | S2: 1900 | T2: 0 | U2: 0 | V2: 1 | W2: 0 | X2: 0.85
A3: APT-00002 | B3: 45978 | C3: Nov | D3: Monday | E3: Morning | F3: Thrissur Physio Center | G3: Thrissur | H3: Arun Raj | I3: PT-1157 | J3: Post-op Rehab | K3: Manual Therapy | L3: Self Pay | M3: Neurologist | N3: Completed | O3: 60 | P3: 60 | Q3: 67.2 | R3: 1550 | S3: 1550 | T3: 0 | U3: 0 | V3: 1 | W3: 0 | X3: 0.85
A4: APT-00003 | B4: 45911 | C4: Sep | D4: Thursday | E4: Morning | F4: Thrissur Physio Center | G4: Thrissur | H4: Sreejith K | I4: PT-1593 | J4: New Patient | K4: Manual Therapy | L4: Government Scheme | M4: Neurologist | N4: Completed | O4: 45 | P4: 45 | Q4: 58.2 | R4: 1050 | S4: 1050 | T4: 0 | U4: 0 | V4: 1 | W4: 0 | X4: 0.85
A5: APT-00004 | B5: 45742 | C5: Mar | D5: Wednesday | E5: Morning | F5: Ernakulam Advanced Rehab | G5: Ernakulam | H5: Rohit George | I5: PT-1637 | J5: Follow-up | K5: Neuro Rehab | L5: Private Insurance | M5: Online Search | N5: Completed | O5: 75 | P5: 75 | Q5: 83.9 | R5: 1900 | S5: 1900 | T5: 0 | U5: 0 | V5: 1 | W5: 0 | X5: 0.85
A6: APT-00005 | B6: 45827 | C6: Jun | D6: Thursday | E6: Afternoon | F6: Ernakulam Advanced Rehab | G6: Ernakulam | H6: Rohit George | I6: PT-1605 | J6: Follow-up | K6: Electrotherapy | L6: Self Pay | M6: Self Referral | N6: Completed | O6: 60 | P6: 60 | Q6: 79.5 | R6: 1500 | S6: 1500 | T6: 0 | U6: 0 | V6: 1 | W6: 0 | X6: 0.85
A7: APT-00006 | B7: 46002 | C7: Dec | D7: Thursday | E7: Afternoon | F7: Ernakulam Advanced Rehab | G7: Ernakulam | H7: Joel Thomas | I7: PT-1042 | J7: Post-op Rehab | K7: Neuro Rehab | L7: Private Insurance | M7: Corporate Wellness | N7: Completed | O7: 90 | P7: 90 | Q7: 108.6 | R7: 2600 | S7: 2600 | T7: 0 | U7: 0 | V7: 1 | W7: 0 | X7: 0.85
A8: APT-00007 | B8: 45700 | C8: Feb | D8: Wednesday | E8: Afternoon | F8: Thrissur Physio Center | G8: Thrissur | H8: Sreejith K | I8: PT-1548 | J8: Follow-up | K8: Neuro Rehab | L8: Corporate Tie-up | M8: Corporate Wellness | N8: Completed | O8: 60 | P8: 60 | Q8: 71.1 | R8: 1250 | S8: 1250 | T8: 0 | U8: 0 | V8: 1 | W8: 0 | X8: 0.85
A9: APT-00008 | B9: 45733 | C9: Mar | D9: Monday | E9: Afternoon | F9: Thrissur Physio Center | G9: Thrissur | H9: Sreejith K | I9: PT-1545 | J9: New Patient | K9: Neuro Rehab | L9: Government Scheme | M9: Self Referral | N9: Completed | O9: 75 | P9: 75 | Q9: 86 | R9: 1700 | S9: 1700 | T9: 0 | U9: 0 | V9: 1 | W9: 0 | X9: 0.85
A10: APT-00009 | B10: 46017 | C10: Dec | D10: Friday | E10: Midday | F10: Ernakulam Advanced Rehab | G10: Ernakulam | H10: Joel Thomas | I10: PT-1198 | J10: Follow-up | K10: Sports Rehab | L10: Government Scheme | M10: Hospital Discharge | N10: Completed | O10: 45 | P10: 45 | Q10: 60.3 | R10: 950 | S10: 950 | T10: 0 | U10: 0 | V10: 1 | W10: 0 | X10: 0.85
A11: APT-00010 | B11: 45962 | C11: Nov | D11: Saturday | E11: Midday | F11: Thrissur Physio Center | G11: Thrissur | H11: Aparna Varma | I11: PT-1052 | J11: Post-op Rehab | K11: Sports Rehab | L11: Self Pay | M11: Neurologist | N11: Completed | O11: 75 | P11: 75 | Q11: 97 | R11: 1950 | S11: 1950 | T11: 0 | U11: 0 | V11: 1 | W11: 0 | X11: 0.85
A12: APT-00011 | B12: 45771 | C12: Apr | D12: Thursday | E12: Morning | F12: Ernakulam Advanced Rehab | G12: Ernakulam | H12: Joel Thomas | I12: PT-1513 | J12: Follow-up | K12: Manual Therapy | L12: Government Scheme | M12: Orthopedic Doctor | N12: No-show | O12: 60 | P12: 0 | Q12: 74.1 | R12: 1300 | S12: 0 | T12: 1300 | U12: 1 | V12: 0 | W12: 0 | X12: 0.85
A13: APT-00012 | B13: 45937 | C13: Oct | D13: Tuesday | E13: Morning | F13: Palakkad Rehab Clinic | G13: Palakkad | H13: Meera S | I13: PT-1353 | J13: Sports Injury | K13: Electrotherapy | L13: Corporate Tie-up | M13: Neurologist | N13: Completed | O13: 75 | P13: 75 | Q13: 90.3 | R13: 1450 | S13: 1450 | T13: 0 | U13: 0 | V13: 1 | W13: 0 | X13: 0.85
... A2001: APT-02000 | B2001: 45727 | C2001: Mar | D2001: Tuesday | E2001: Morning | F2001: Thrissur Physio Center | G2001: Thrissur | H2001: Aparna Varma | I2001: PT-1465 | J2001: Chronic Pain | K2001: Exercise Therapy | L2001: Self Pay | M2001: Corporate Wellness | N2001: Completed | O2001: 30 | P2001: 30 | Q2001: 35.8 | R2001: 700 | S2001: 700 | T2001: 0 | U2001: 0 | V2001: 1 | W2001: 0 | X2001: 0.85

Sheet KPI_Summary
A1: Metric | B1: Value
A2: Total Appointments | B2: 2000
A3: Total Revenue INR | B3: 1990900
A4: Overall No-Show % | B4: 0.151
A5: Average Utilization % | B5: 0.6249501
A6: Lost Revenue INR | B6: 543350

Sheet What_If_Model
A1: No_Show_Reduction_% | B1: Potential_Recovered_Revenue_INR | C1: Remaining_No_Show_Loss_INR
A2: 0 | B2: 0 | C2: 403000
A3: 5 | B3: 20150 | C3: 382850
A4: 10 | B4: 40300 | C4: 362700
A5: 15 | B5: 60450 | C5: 342550
A6: 20 | B6: 80600 | C6: 322400
A7: 25 | B7: 100750 | C7: 302250
A8: 30 | B8: 120900 | C8: 282100
A9: 35 | B9: 141050 | C9: 261950
A10: 40 | B10: 161200 | C10: 241800
A11: 45 | B11: 181350 | C11: 221650
A12: 50 | B12: 201500 | C12: 201500

Sheet Data_Dictionary
A1: Field | B1: Dashboard Use
A2: Appointment_ID | B2: Unique appointment identifier
A3: Appointment_Date | B3: Scheduled date across 2025
A4: Clinic/District | B4: Three Kerala regions: Palakkad, Thrissur, Ernakulam
A5: Appointment_Status | B5: Completed, No-show, Cancelled Late, or Rescheduled
A6: Revenue_INR | B6: Earned revenue for completed sessions
A7: Lost_Revenue_INR | B7: Potential revenue missed for no-shows/late cancellations
A8: No_Show_Flag | B8: Average this field to calculate No-Show %
A9: Allocated_Shift_Capacity_Minutes | B9: Use SUM(Treated_Minutes)/SUM(Allocated_Shift_Capacity_Minutes) for utilization
A10: Utilization_Target | B10: 85% benchmark

Sheet Dashboard
A1: EXCEL CLINICAL OPS DASHBOARD | OUTPATIENT REHAB OPTIMIZATION | J1: FY 2024-25 | N1: Day of Week | O1: No-Show Rate | Q1: Therapist | R1: Utilization % | S1: 85% Target | U1: Therapy_Type | V1: Completed | W1: Rescheduled | X1: No-show | Y1: Cancelled Late | AA1: Therapy Type | AB1: Revenue Generated | AC1: Revenue Lost
N2: Monday | O2: {=IFERROR(SUMPRODUCT((Appointments_Tbl[Day_of_Week]=N2)*(SUBTOTAL(103,OFFSET(INDEX(Appointments_Tbl[Appointment_ID],1),ROW(Appointments_Tbl[Appointment_ID])-ROW(INDEX(Appointments_Tbl[Appointment_ID],1)),0,1)))*(Appointments_Tbl[No_Show_Flag]))/SUMPRODUCT((Appointments_Tbl[Day_of_Week]=N2)*(SUBTOTAL(103,OFFSET(INDEX(Appointments_Tbl[Appointment_ID],1),ROW(Appointments_Tbl[Appointment_ID])-ROW(INDEX(Appointments_Tbl[Appointment_ID],1)),0,1)))),0)} -> 0.19085487 | Q2: Aparna Varma | R2: {=IFERROR(SUMPRODUCT((Appointments_Tbl[Therapist]=Q2)*(SUBTOTAL(103,OFFSET(INDEX(Appointments_Tbl[Appointment_ID],1),ROW(Appointments_Tbl[Appointment_ID])-ROW(INDEX(Appointments_Tbl[Appointment_ID],1)),0,1)))*Appointments_Tbl[Treated_Minutes])/SUMPRODUCT((Appointments_Tbl[Therapist]=Q2)*(SUBTOTAL(103,OFFSET(INDEX(Appointments_Tbl[Appointment_ID],1),ROW(Appointments_Tbl[Appointment_ID])-ROW(INDEX(Appointments_Tbl[Appointment_ID],1)),0,1)))*Appointments_Tbl[Allocated_Shift_Capacity_Minutes]),0)} -> 0.66660131 | S2: 0.85 | U2: Neuro Rehab | V2: {=SUMPRODUCT((Appointments_Tbl[Therapy_Type]=$U2)*(Appointments_Tbl[Appointment_Status]=V$1)*(SUBTOTAL(103,OFFSET(INDEX(Appointments_Tbl[Appointment_ID],1),ROW(Appointments_Tbl[Appointment_ID])-ROW(INDEX(Appointments_Tbl[Appointment_ID],1)),0,1))))} -> 278 | W2: {=SUMPRODUCT((Appointments_Tbl[Therapy_Type]=$U2)*(Appointments_Tbl[Appointment_Status]=W$1)*(SUBTOTAL(103,OFFSET(INDEX(Appointments_Tbl[Appointment_ID],1),ROW(Appointments_Tbl[Appointment_ID])-ROW(INDEX(Appointments_Tbl[Appointment_ID],1)),0,1))))} -> 8 | X2: {=SUMPRODUCT((Appointments_Tbl[Therapy_Type]=$U2)*(Appointments_Tbl[Appointment_Status]=X$1)*(SUBTOTAL(103,OFFSET(INDEX(Appointments_Tbl[Appointment_ID],1),ROW(Appointments_Tbl[Appointment_ID])-ROW(INDEX(Appointments_Tbl[Appointment_ID],1)),0,1))))} -> 48 | Y2: {=SUMPRODUCT((Appointments_Tbl[Therapy_Type]=$U2)*(Appointments_Tbl[Appointment_Status]=Y$1)*(SUBTOTAL(103,OFFSET(INDEX(Appointments_Tbl[Appointment_ID],1),ROW(Appointments_Tbl[Appointment_ID])-ROW(INDEX(Appointments_Tbl[Appointment_ID],1)),0,1))))} -> 17 | AA2: Neuro Rehab | AB2: {=SUMPRODUCT((Appointments_Tbl[Therapy_Type]=$AA2)*(SUBTOTAL(103,OFFSET(INDEX(Appointments_Tbl[Appointment_ID],1),ROW(Appointments_Tbl[Appointment_ID])-ROW(INDEX(Appointments_Tbl[Appointment_ID],1)),0,1)))*(Appointments_Tbl[Revenue_INR]))} -> 365500 | AC2: {=SUMPRODUCT((Appointments_Tbl[Therapy_Type]=$AA2)*(SUBTOTAL(103,OFFSET(INDEX(Appointments_Tbl[Appointment_ID],1),ROW(Appointments_Tbl[Appointment_ID])-ROW(INDEX(Appointments_Tbl[Appointment_ID],1)),0,1)))*(Appointments_Tbl[Lost_Revenue_INR]))} -> 87100
A3: Total Revenue Generated | D3: Overall No-Show Rate | G3: Avg Therapist Utilization | J3: Total Lost Revenue | N3: Tuesday | O3: {=IFERROR(SUMPRODUCT((Appointments_Tbl[Day_of_Week]=N3)*(SUBTOTAL(103,OFFSET(INDEX(Appointments_Tbl[Appointment_ID],1),ROW(Appointments_Tbl[Appointment_ID])-ROW(INDEX(Appointments_Tbl[Appointment_ID],1)),0,1)))*(Appointments_Tbl[No_Show_Flag]))/SUMPRODUCT((Appointments_Tbl[Day_of_Week]=N3)*(SUBTOTAL(103,OFFSET(INDEX(Appointments_Tbl[Appointment_ID],1),ROW(Appointments_Tbl[Appointment_ID])-ROW(INDEX(Appointments_Tbl[Appointment_ID],1)),0,1)))),0)} -> 0.1433121 | Q3: Lakshmi Pillai | R3: {=IFERROR(SUMPRODUCT((Appointments_Tbl[Therapist]=Q3)*(SUBTOTAL(103,OFFSET(INDEX(Appointments_Tbl[Appointment_ID],1),ROW(Appointments_Tbl[Appointment_ID])-ROW(INDEX(Appointments_Tbl[Appointment_ID],1)),0,1)))*Appointments_Tbl[Treated_Minutes])/SUMPRODUCT((Appointments_Tbl[Therapist]=Q3)*(SUBTOTAL(103,OFFSET(INDEX(Appointments_Tbl[Appointment_ID],1),ROW(Appointments_Tbl[Appointment_ID])-ROW(INDEX(Appointments_Tbl[Appointment_ID],1)),0,1)))*Appointments_Tbl[Allocated_Shift_Capacity_Minutes]),0)} -> 0.66237377 | S3: 0.85 | U3: Manual Therapy | V3: {=SUMPRODUCT((Appointments_Tbl[Therapy_Type]=$U3)*(Appointments_Tbl[Appointment_Status]=V$1)*(SUBTOTAL(103,OFFSET(INDEX(Appointments_Tbl[Appointment_ID],1),ROW(Appointments_Tbl[Appointment_ID])-ROW(INDEX(Appointments_Tbl[Appointment_ID],1)),0,1))))} -> 255 | W3: {=SUMPRODUCT((Appointments_Tbl[Therapy_Type]=$U3)*(Appointments_Tbl[Appointment_Status]=W$1)*(SUBTOTAL(103,OFFSET(INDEX(Appointments_Tbl[Appointment_ID],1),ROW(Appointments_Tbl[Appointment_ID])-ROW(INDEX(Appointments_Tbl[Appointment_ID],1)),0,1))))} -> 18 | X3: {=SUMPRODUCT((Appointments_Tbl[Therapy_Type]=$U3)*(Appointments_Tbl[Appointment_Status]=X$1)*(SUBTOTAL(103,OFFSET(INDEX(Appointments_Tbl[Appointment_ID],1),ROW(Appointments_Tbl[Appointment_ID])-ROW(INDEX(Appointments_Tbl[Appointment_ID],1)),0,1))))} -> 56 | Y3: {=SUMPRODUCT((Appointments_Tbl[Therapy_Type]=$U3)*(Appointments_Tbl[Appointment_Status]=Y$1)*(SUBTOTAL(103,OFFSET(INDEX(Appointments_Tbl[Appointment_ID],1),ROW(Appointments_Tbl[Appointment_ID])-ROW(INDEX(Appointments_Tbl[Appointment_ID],1)),0,1))))} -> 18 | AA3: Manual Therapy | AB3: {=SUMPRODUCT((Appointments_Tbl[Therapy_Type]=$AA3)*(SUBTOTAL(103,OFFSET(INDEX(Appointments_Tbl[Appointment_ID],1),ROW(Appointments_Tbl[Appointment_ID])-ROW(INDEX(Appointments_Tbl[Appointment_ID],1)),0,1)))*(Appointments_Tbl[Revenue_INR]))} -> 328950 | AC3: {=SUMPRODUCT((Appointments_Tbl[Therapy_Type]=$AA3)*(SUBTOTAL(103,OFFSET(INDEX(Appointments_Tbl[Appointment_ID],1),ROW(Appointments_Tbl[Appointment_ID])-ROW(INDEX(Appointments_Tbl[Appointment_ID],1)),0,1)))*(Appointments_Tbl[Lost_Revenue_INR]))} -> 96150
N4: Wednesday | O4: {=IFERROR(SUMPRODUCT((Appointments_Tbl[Day_of_Week]=N4)*(SUBTOTAL(103,OFFSET(INDEX(Appointments_Tbl[Appointment_ID],1),ROW(Appointments_Tbl[Appointment_ID])-ROW(INDEX(Appointments_Tbl[Appointment_ID],1)),0,1)))*(Appointments_Tbl[No_Show_Flag]))/SUMPRODUCT((Appointments_Tbl[Day_of_Week]=N4)*(SUBTOTAL(103,OFFSET(INDEX(Appointments_Tbl[Appointment_ID],1),ROW(Appointments_Tbl[Appointment_ID])-ROW(INDEX(Appointments_Tbl[Appointment_ID],1)),0,1)))),0)} -> 0.14576271 | Q4: Joel Thomas | R4: {=IFERROR(SUMPRODUCT((Appointments_Tbl[Therapist]=Q4)*(SUBTOTAL(103,OFFSET(INDEX(Appointments_Tbl[Appointment_ID],1),ROW(Appointments_Tbl[Appointment_ID])-ROW(INDEX(Appointments_Tbl[Appointment_ID],1)),0,1)))*Appointments_Tbl[Treated_Minutes])/SUMPRODUCT((Appointments_Tbl[Therapist]=Q4)*(SUBTOTAL(103,OFFSET(INDEX(Appointments_Tbl[Appointment_ID],1),ROW(Appointments_Tbl[Appointment_ID])-ROW(INDEX(Appointments_Tbl[Appointment_ID],1)),0,1)))*Appointments_Tbl[Allocated_Shift_Capacity_Minutes]),0)} -> 0.66186794 | S4: 0.85 | U4: Posture Correction | V4: {=SUMPRODUCT((Appointments_Tbl[Therapy_Type]=$U4)*(Appointments_Tbl[Appointment_Status]=V$1)*(SUBTOTAL(103,OFFSET(INDEX(Appointments_Tbl[Appointment_ID],1),ROW(Appointments_Tbl[Appointment_ID])-ROW(INDEX(Appointments_Tbl[Appointment_ID],1)),0,1))))} -> 252 | W4: {=SUMPRODUCT((Appointments_Tbl[Therapy_Type]=$U4)*(Appointments_Tbl[Appointment_Status]=W$1)*(SUBTOTAL(103,OFFSET(INDEX(Appointments_Tbl[Appointment_ID],1),ROW(Appointments_Tbl[Appointment_ID])-ROW(INDEX(Appointments_Tbl[Appointment_ID],1)),0,1))))} -> 11 | X4: {=SUMPRODUCT((Appointments_Tbl[Therapy_Type]=$U4)*(Appointments_Tbl[Appointment_Status]=X$1)*(SUBTOTAL(103,OFFSET(INDEX(Appointments_Tbl[Appointment_ID],1),ROW(Appointments_Tbl[Appointment_ID])-ROW(INDEX(Appointments_Tbl[Appointment_ID],1)),0,1))))} -> 53 | Y4: {=SUMPRODUCT((Appointments_Tbl[Therapy_Type]=$U4)*(Appointments_Tbl[Appointment_Status]=Y$1)*(SUBTOTAL(103,OFFSET(INDEX(Appointments_Tbl[Appointment_ID],1),ROW(Appointments_Tbl[Appointment_ID])-ROW(INDEX(Appointments_Tbl[Appointment_ID],1)),0,1))))} -> 21 | AA4: Posture Correction | AB4: {=SUMPRODUCT((Appointments_Tbl[Therapy_Type]=$AA4)*(SUBTOTAL(103,OFFSET(INDEX(Appointments_Tbl[Appointment_ID],1),ROW(Appointments_Tbl[Appointment_ID])-ROW(INDEX(Appointments_Tbl[Appointment_ID],1)),0,1)))*(Appointments_Tbl[Revenue_INR]))} -> 330500 | AC4: {=SUMPRODUCT((Appointments_Tbl[Therapy_Type]=$AA4)*(SUBTOTAL(103,OFFSET(INDEX(Appointments_Tbl[Appointment_ID],1),ROW(Appointments_Tbl[Appointment_ID])-ROW(INDEX(Appointments_Tbl[Appointment_ID],1)),0,1)))*(Appointments_Tbl[Lost_Revenue_INR]))} -> 95750
A5: =SUM(Appointments_Tbl[Revenue_INR]) -> 1990900 | D5: =AVERAGE(Appointments_Tbl[No_Show_Flag]) -> 0.151 | G5: =SUM(Appointments_Tbl[Treated_Minutes])/SUM(Appointments_Tbl[Allocated_Shift_Capacity_Minutes]) -> 0.6249501 | J5: =SUM(Appointments_Tbl[Lost_Revenue_INR]) -> 543350 | N5: Thursday | O5: {=IFERROR(SUMPRODUCT((Appointments_Tbl[Day_of_Week]=N5)*(SUBTOTAL(103,OFFSET(INDEX(Appointments_Tbl[Appointment_ID],1),ROW(Appointments_Tbl[Appointment_ID])-ROW(INDEX(Appointments_Tbl[Appointment_ID],1)),0,1)))*(Appointments_Tbl[No_Show_Flag]))/SUMPRODUCT((Appointments_Tbl[Day_of_Week]=N5)*(SUBTOTAL(103,OFFSET(INDEX(Appointments_Tbl[Appointment_ID],1),ROW(Appointments_Tbl[Appointment_ID])-ROW(INDEX(Appointments_Tbl[Appointment_ID],1)),0,1)))),0)} -> 0.11481481 | Q5: Fathima Rahman | R5: {=IFERROR(SUMPRODUCT((Appointments_Tbl[Therapist]=Q5)*(SUBTOTAL(103,OFFSET(INDEX(Appointments_Tbl[Appointment_ID],1),ROW(Appointments_Tbl[Appointment_ID])-ROW(INDEX(Appointments_Tbl[Appointment_ID],1)),0,1)))*Appointments_Tbl[Treated_Minutes])/SUMPRODUCT((Appointments_Tbl[Therapist]=Q5)*(SUBTOTAL(103,OFFSET(INDEX(Appointments_Tbl[Appointment_ID],1),ROW(Appointments_Tbl[Appointment_ID])-ROW(INDEX(Appointments_Tbl[Appointment_ID],1)),0,1)))*Appointments_Tbl[Allocated_Shift_Capacity_Minutes]),0)} -> 0.64746521 | S5: 0.85 | U5: Exercise Therapy | V5: {=SUMPRODUCT((Appointments_Tbl[Therapy_Type]=$U5)*(Appointments_Tbl[Appointment_Status]=V$1)*(SUBTOTAL(103,OFFSET(INDEX(Appointments_Tbl[Appointment_ID],1),ROW(Appointments_Tbl[Appointment_ID])-ROW(INDEX(Appointments_Tbl[Appointment_ID],1)),0,1))))} -> 248 | W5: {=SUMPRODUCT((Appointments_Tbl[Therapy_Type]=$U5)*(Appointments_Tbl[Appointment_Status]=W$1)*(SUBTOTAL(103,OFFSET(INDEX(Appointments_Tbl[Appointment_ID],1),ROW(Appointments_Tbl[Appointment_ID])-ROW(INDEX(Appointments_Tbl[Appointment_ID],1)),0,1))))} -> 10 | X5: {=SUMPRODUCT((Appointments_Tbl[Therapy_Type]=$U5)*(Appointments_Tbl[Appointment_Status]=X$1)*(SUBTOTAL(103,OFFSET(INDEX(Appointments_Tbl[Appointment_ID],1),ROW(Appointments_Tbl[Appointment_ID])-ROW(INDEX(Appointments_Tbl[Appointment_ID],1)),0,1))))} -> 56 | Y5: {=SUMPRODUCT((Appointments_Tbl[Therapy_Type]=$U5)*(Appointments_Tbl[Appointment_Status]=Y$1)*(SUBTOTAL(103,OFFSET(INDEX(Appointments_Tbl[Appointment_ID],1),ROW(Appointments_Tbl[Appointment_ID])-ROW(INDEX(Appointments_Tbl[Appointment_ID],1)),0,1))))} -> 17 | AA5: Exercise Therapy | AB5: {=SUMPRODUCT((Appointments_Tbl[Therapy_Type]=$AA5)*(SUBTOTAL(103,OFFSET(INDEX(Appointments_Tbl[Appointment_ID],1),ROW(Appointments_Tbl[Appointment_ID])-ROW(INDEX(Appointments_Tbl[Appointment_ID],1)),0,1)))*(Appointments_Tbl[Revenue_INR]))} -> 319300 | AC5: {=SUMPRODUCT((Appointments_Tbl[Therapy_Type]=$AA5)*(SUBTOTAL(103,OFFSET(INDEX(Appointments_Tbl[Appointment_ID],1),ROW(Appointments_Tbl[Appointment_ID])-ROW(INDEX(Appointments_Tbl[Appointment_ID],1)),0,1)))*(Appointments_Tbl[Lost_Revenue_INR]))} -> 95600
A6: from Completed Sessions | D6: Goal <10% | G6: Target: 85% | J6: from Missed Appointments | N6: Friday | O6: {=IFERROR(SUMPRODUCT((Appointments_Tbl[Day_of_Week]=N6)*(SUBTOTAL(103,OFFSET(INDEX(Appointments_Tbl[Appointment_ID],1),ROW(Appointments_Tbl[Appointment_ID])-ROW(INDEX(Appointments_Tbl[Appointment_ID],1)),0,1)))*(Appointments_Tbl[No_Show_Flag]))/SUMPRODUCT((Appointments_Tbl[Day_of_Week]=N6)*(SUBTOTAL(103,OFFSET(INDEX(Appointments_Tbl[Appointment_ID],1),ROW(Appointments_Tbl[Appointment_ID])-ROW(INDEX(Appointments_Tbl[Appointment_ID],1)),0,1)))),0)} -> 0.11184211 | Q6: Divya Nambiar | R6: {=IFERROR(SUMPRODUCT((Appointments_Tbl[Therapist]=Q6)*(SUBTOTAL(103,OFFSET(INDEX(Appointments_Tbl[Appointment_ID],1),ROW(Appointments_Tbl[Appointment_ID])-ROW(INDEX(Appointments_Tbl[Appointment_ID],1)),0,1)))*Appointments_Tbl[Treated_Minutes])/SUMPRODUCT((Appointments_Tbl[Therapist]=Q6)*(SUBTOTAL(103,OFFSET(INDEX(Appointments_Tbl[Appointment_ID],1),ROW(Appointments_Tbl[Appointment_ID])-ROW(INDEX(Appointments_Tbl[Appointment_ID],1)),0,1)))*Appointments_Tbl[Allocated_Shift_Capacity_Minutes]),0)} -> 0.64746001 | S6: 0.85 | U6: Sports Rehab | V6: {=SUMPRODUCT((Appointments_Tbl[Therapy_Type]=$U6)*(Appointments_Tbl[Appointment_Status]=V$1)*(SUBTOTAL(103,OFFSET(INDEX(Appointments_Tbl[Appointment_ID],1),ROW(Appointments_Tbl[Appointment_ID])-ROW(INDEX(Appointments_Tbl[Appointment_ID],1)),0,1))))} -> 236 | W6: {=SUMPRODUCT((Appointments_Tbl[Therapy_Type]=$U6)*(Appointments_Tbl[Appointment_Status]=W$1)*(SUBTOTAL(103,OFFSET(INDEX(Appointments_Tbl[Appointment_ID],1),ROW(Appointments_Tbl[Appointment_ID])-ROW(INDEX(Appointments_Tbl[Appointment_ID],1)),0,1))))} -> 14 | X6: {=SUMPRODUCT((Appointments_Tbl[Therapy_Type]=$U6)*(Appointments_Tbl[Appointment_Status]=X$1)*(SUBTOTAL(103,OFFSET(INDEX(Appointments_Tbl[Appointment_ID],1),ROW(Appointments_Tbl[Appointment_ID])-ROW(INDEX(Appointments_Tbl[Appointment_ID],1)),0,1))))} -> 49 | Y6: {=SUMPRODUCT((Appointments_Tbl[Therapy_Type]=$U6)*(Appointments_Tbl[Appointment_Status]=Y$1)*(SUBTOTAL(103,OFFSET(INDEX(Appointments_Tbl[Appointment_ID],1),ROW(Appointments_Tbl[Appointment_ID])-ROW(INDEX(Appointments_Tbl[Appointment_ID],1)),0,1))))} -> 22 | AA6: Sports Rehab | AB6: {=SUMPRODUCT((Appointments_Tbl[Therapy_Type]=$AA6)*(SUBTOTAL(103,OFFSET(INDEX(Appointments_Tbl[Appointment_ID],1),ROW(Appointments_Tbl[Appointment_ID])-ROW(INDEX(Appointments_Tbl[Appointment_ID],1)),0,1)))*(Appointments_Tbl[Revenue_INR]))} -> 318550 | AC6: {=SUMPRODUCT((Appointments_Tbl[Therapy_Type]=$AA6)*(SUBTOTAL(103,OFFSET(INDEX(Appointments_Tbl[Appointment_ID],1),ROW(Appointments_Tbl[Appointment_ID])-ROW(INDEX(Appointments_Tbl[Appointment_ID],1)),0,1)))*(Appointments_Tbl[Lost_Revenue_INR]))} -> 94600
N7: Saturday | O7: =SUMIFS(Appointments_Tbl[No_Show_Flag],Appointments_Tbl[Day_of_Week],N7)/COUNTIF(Appointments_Tbl[Day_of_Week],N7) -> 0.18021201 | Q7: Rohit George | R7: {=IFERROR(SUMPRODUCT((Appointments_Tbl[Therapist]=Q7)*(SUBTOTAL(103,OFFSET(INDEX(Appointments_Tbl[Appointment_ID],1),ROW(Appointments_Tbl[Appointment_ID])-ROW(INDEX(Appointments_Tbl[Appointment_ID],1)),0,1)))*Appointments_Tbl[Treated_Minutes])/SUMPRODUCT((Appointments_Tbl[Therapist]=Q7)*(SUBTOTAL(103,OFFSET(INDEX(Appointments_Tbl[Appointment_ID],1),ROW(Appointments_Tbl[Appointment_ID])-ROW(INDEX(Appointments_Tbl[Appointment_ID],1)),0,1)))*Appointments_Tbl[Allocated_Shift_Capacity_Minutes]),0)} -> 0.64101194 | S7: 0.85 | U7: Electrotherapy | V7: {=SUMPRODUCT((Appointments_Tbl[Therapy_Type]=$U7)*(Appointments_Tbl[Appointment_Status]=V$1)*(SUBTOTAL(103,OFFSET(INDEX(Appointments_Tbl[Appointment_ID],1),ROW(Appointments_Tbl[Appointment_ID])-ROW(INDEX(Appointments_Tbl[Appointment_ID],1)),0,1))))} -> 248 | W7: {=SUMPRODUCT((Appointments_Tbl[Therapy_Type]=$U7)*(Appointments_Tbl[Appointment_Status]=W$1)*(SUBTOTAL(103,OFFSET(INDEX(Appointments_Tbl[Appointment_ID],1),ROW(Appointments_Tbl[Appointment_ID])-ROW(INDEX(Appointments_Tbl[Appointment_ID],1)),0,1))))} -> 10 | X7: {=SUMPRODUCT((Appointments_Tbl[Therapy_Type]=$U7)*(Appointments_Tbl[Appointment_Status]=X$1)*(SUBTOTAL(103,OFFSET(INDEX(Appointments_Tbl[Appointment_ID],1),ROW(Appointments_Tbl[Appointment_ID])-ROW(INDEX(Appointments_Tbl[Appointment_ID],1)),0,1))))} -> 40 | Y7: {=SUMPRODUCT((Appointments_Tbl[Therapy_Type]=$U7)*(Appointments_Tbl[Appointment_Status]=Y$1)*(SUBTOTAL(103,OFFSET(INDEX(Appointments_Tbl[Appointment_ID],1),ROW(Appointments_Tbl[Appointment_ID])-ROW(INDEX(Appointments_Tbl[Appointment_ID],1)),0,1))))} -> 15 | AA7: Electrotherapy | AB7: {=SUMPRODUCT((Appointments_Tbl[Therapy_Type]=$AA7)*(SUBTOTAL(103,OFFSET(INDEX(Appointments_Tbl[Appointment_ID],1),ROW(Appointments_Tbl[Appointment_ID])-ROW(INDEX(Appointments_Tbl[Appointment_ID],1)),0,1)))*(Appointments_Tbl[Revenue_INR]))} -> 328100 | AC7: {=SUMPRODUCT((Appointments_Tbl[Therapy_Type]=$AA7)*(SUBTOTAL(103,OFFSET(INDEX(Appointments_Tbl[Appointment_ID],1),ROW(Appointments_Tbl[Appointment_ID])-ROW(INDEX(Appointments_Tbl[Appointment_ID],1)),0,1)))*(Appointments_Tbl[Lost_Revenue_INR]))} -> 74150
N8: Sunday | O8: =SUMIFS(Appointments_Tbl[No_Show_Flag],Appointments_Tbl[Day_of_Week],N8)/COUNTIF(Appointments_Tbl[Day_of_Week],N8) -> 0.064516129 | Q8: Rahul P | R8: {=IFERROR(SUMPRODUCT((Appointments_Tbl[Therapist]=Q8)*(SUBTOTAL(103,OFFSET(INDEX(Appointments_Tbl[Appointment_ID],1),ROW(Appointments_Tbl[Appointment_ID])-ROW(INDEX(Appointments_Tbl[Appointment_ID],1)),0,1)))*Appointments_Tbl[Treated_Minutes])/SUMPRODUCT((Appointments_Tbl[Therapist]=Q8)*(SUBTOTAL(103,OFFSET(INDEX(Appointments_Tbl[Appointment_ID],1),ROW(Appointments_Tbl[Appointment_ID])-ROW(INDEX(Appointments_Tbl[Appointment_ID],1)),0,1)))*Appointments_Tbl[Allocated_Shift_Capacity_Minutes]),0)} -> 0.63237149 | S8: 0.85 | AA8: Total | AB8: =SUM(AB2:AB7) -> 1990900 | AC8: =SUM(AC2:AC7) -> 543350
C9: NO-SHOW RATE BY DAY OF WEEK | G9: THERAPIST UTILIZATION VS 85% TARGET | Q9: Nisha Thomas | R9: {=IFERROR(SUMPRODUCT((Appointments_Tbl[Therapist]=Q9)*(SUBTOTAL(103,OFFSET(INDEX(Appointments_Tbl[Appointment_ID],1),ROW(Appointments_Tbl[Appointment_ID])-ROW(INDEX(Appointments_Tbl[Appointment_ID],1)),0,1)))*Appointments_Tbl[Treated_Minutes])/SUMPRODUCT((Appointments_Tbl[Therapist]=Q9)*(SUBTOTAL(103,OFFSET(INDEX(Appointments_Tbl[Appointment_ID],1),ROW(Appointments_Tbl[Appointment_ID])-ROW(INDEX(Appointments_Tbl[Appointment_ID],1)),0,1)))*Appointments_Tbl[Allocated_Shift_Capacity_Minutes]),0)} -> 0.62809716 | S9: 0.85
Q10: Priya Mathew | R10: {=IFERROR(SUMPRODUCT((Appointments_Tbl[Therapist]=Q10)*(SUBTOTAL(103,OFFSET(INDEX(Appointments_Tbl[Appointment_ID],1),ROW(Appointments_Tbl[Appointment_ID])-ROW(INDEX(Appointments_Tbl[Appointment_ID],1)),0,1)))*Appointments_Tbl[Treated_Minutes])/SUMPRODUCT((Appointments_Tbl[Therapist]=Q10)*(SUBTOTAL(103,OFFSET(INDEX(Appointments_Tbl[Appointment_ID],1),ROW(Appointments_Tbl[Appointment_ID])-ROW(INDEX(Appointments_Tbl[Appointment_ID],1)),0,1)))*Appointments_Tbl[Allocated_Shift_Capacity_Minutes]),0)} -> 0.6186575 | S10: 0.85
Q11: Anjali Menon | R11: {=IFERROR(SUMPRODUCT((Appointments_Tbl[Therapist]=Q11)*(SUBTOTAL(103,OFFSET(INDEX(Appointments_Tbl[Appointment_ID],1),ROW(Appointments_Tbl[Appointment_ID])-ROW(INDEX(Appointments_Tbl[Appointment_ID],1)),0,1)))*Appointments_Tbl[Treated_Minutes])/SUMPRODUCT((Appointments_Tbl[Therapist]=Q11)*(SUBTOTAL(103,OFFSET(INDEX(Appointments_Tbl[Appointment_ID],1),ROW(Appointments_Tbl[Appointment_ID])-ROW(INDEX(Appointments_Tbl[Appointment_ID],1)),0,1)))*Appointments_Tbl[Allocated_Shift_Capacity_Minutes]),0)} -> 0.61593738 | S11: 0.85
Q12: Vishnu Nair | R12: {=IFERROR(SUMPRODUCT((Appointments_Tbl[Therapist]=Q12)*(SUBTOTAL(103,OFFSET(INDEX(Appointments_Tbl[Appointment_ID],1),ROW(Appointments_Tbl[Appointment_ID])-ROW(INDEX(Appointments_Tbl[Appointment_ID],1)),0,1)))*Appointments_Tbl[Treated_Minutes])/SUMPRODUCT((Appointments_Tbl[Therapist]=Q12)*(SUBTOTAL(103,OFFSET(INDEX(Appointments_Tbl[Appointment_ID],1),ROW(Appointments_Tbl[Appointment_ID])-ROW(INDEX(Appointments_Tbl[Appointment_ID],1)),0,1)))*Appointments_Tbl[Allocated_Shift_Capacity_Minutes]),0)} -> 0.61320978 | S12: 0.85 | U12: Month | V12: Appointments
Q13: Arun Raj | R13: {=IFERROR(SUMPRODUCT((Appointments_Tbl[Therapist]=Q13)*(SUBTOTAL(103,OFFSET(INDEX(Appointments_Tbl[Appointment_ID],1),ROW(Appointments_Tbl[Appointment_ID])-ROW(INDEX(Appointments_Tbl[Appointment_ID],1)),0,1)))*Appointments_Tbl[Treated_Minutes])/SUMPRODUCT((Appointments_Tbl[Therapist]=Q13)*(SUBTOTAL(103,OFFSET(INDEX(Appointments_Tbl[Appointment_ID],1),ROW(Appointments_Tbl[Appointment_ID])-ROW(INDEX(Appointments_Tbl[Appointment_ID],1)),0,1)))*Appointments_Tbl[Allocated_Shift_Capacity_Minutes]),0)} -> 0.60706597 | S13: 0.85 | U13: Jan | V13: =COUNTIFS(Appointments_Tbl[Month],U13) -> 159
Q14: Meera S | R14: {=IFERROR(SUMPRODUCT((Appointments_Tbl[Therapist]=Q14)*(SUBTOTAL(103,OFFSET(INDEX(Appointments_Tbl[Appointment_ID],1),ROW(Appointments_Tbl[Appointment_ID])-ROW(INDEX(Appointments_Tbl[Appointment_ID],1)),0,1)))*Appointments_Tbl[Treated_Minutes])/SUMPRODUCT((Appointments_Tbl[Therapist]=Q14)*(SUBTOTAL(103,OFFSET(INDEX(Appointments_Tbl[Appointment_ID],1),ROW(Appointments_Tbl[Appointment_ID])-ROW(INDEX(Appointments_Tbl[Appointment_ID],1)),0,1)))*Appointments_Tbl[Allocated_Shift_Capacity_Minutes]),0)} -> 0.58411353 | S14: 0.85 | U14: Feb | V14: =COUNTIFS(Appointments_Tbl[Month],U14) -> 165
Q15: Sreejith K | R15: {=IFERROR(SUMPRODUCT((Appointments_Tbl[Therapist]=Q15)*(SUBTOTAL(103,OFFSET(INDEX(Appointments_Tbl[Appointment_ID],1),ROW(Appointments_Tbl[Appointment_ID])-ROW(INDEX(Appointments_Tbl[Appointment_ID],1)),0,1)))*Appointments_Tbl[Treated_Minutes])/SUMPRODUCT((Appointments_Tbl[Therapist]=Q15)*(SUBTOTAL(103,OFFSET(INDEX(Appointments_Tbl[Appointment_ID],1),ROW(Appointments_Tbl[Appointment_ID])-ROW(INDEX(Appointments_Tbl[Appointment_ID],1)),0,1)))*Appointments_Tbl[Allocated_Shift_Capacity_Minutes]),0)} -> 0.58284636 | S15: 0.85 | U15: Mar | V15: =COUNTIFS(Appointments_Tbl[Month],U15) -> 174
Q16: Deepa Krishnan | R16: {=IFERROR(SUMPRODUCT((Appointments_Tbl[Therapist]=Q16)*(SUBTOTAL(103,OFFSET(INDEX(Appointments_Tbl[Appointment_ID],1),ROW(Appointments_Tbl[Appointment_ID])-ROW(INDEX(Appointments_Tbl[Appointment_ID],1)),0,1)))*Appointments_Tbl[Treated_Minutes])/SUMPRODUCT((Appointments_Tbl[Therapist]=Q16)*(SUBTOTAL(103,OFFSET(INDEX(Appointments_Tbl[Appointment_ID],1),ROW(Appointments_Tbl[Appointment_ID])-ROW(INDEX(Appointments_Tbl[Appointment_ID],1)),0,1)))*Appointments_Tbl[Allocated_Shift_Capacity_Minutes]),0)} -> 0.55374818 | S16: 0.85 | U16: Apr | V16: =COUNTIFS(Appointments_Tbl[Month],U16) -> 152
U17: May | V17: =COUNTIFS(Appointments_Tbl[Month],U17) -> 170
U18: Jun | V18: =COUNTIFS(Appointments_Tbl[Month],U18) -> 175
N19: THERAPIST DETAILS | U19: Jul | V19: =COUNTIFS(Appointments_Tbl[Month],U19) -> 171
N20: Select Therapist: | O20: Rahul P | U20: Aug | V20: =COUNTIFS(Appointments_Tbl[Month],U20) -> 175
N21: Utilization %: | O21: =IFERROR(INDEX($R$2:$R$16,MATCH($O$20,$Q$2:$Q$16,0)),"n/a") -> 0.63237149 | U21: Sep | V21: =COUNTIFS(Appointments_Tbl[Month],U21) -> 166
N22: Total Appointments: | O22: =COUNTIFS(Appointments_Tbl[Therapist],$O$20) -> 118 | U22: Oct | V22: =COUNTIFS(Appointments_Tbl[Month],U22) -> 166
N23: No-Show Count: | O23: =SUMIFS(Appointments_Tbl[No_Show_Flag],Appointments_Tbl[Therapist],$O$20) -> 19 | U23: Nov | V23: =COUNTIFS(Appointments_Tbl[Month],U23) -> 148
C24: VOLUME & STATUS BREAKDOWN BY CLINICAL SPECIALITY / THERAPY | N24: Revenue Generated (INR): | O24: =SUMIFS(Appointments_Tbl[Revenue_INR],Appointments_Tbl[Therapist],$O$20) -> 108600 | U24: Dec | V24: =COUNTIFS(Appointments_Tbl[Month],U24) -> 179
C46: REVENUE CLINIC X THERAPY
C66: MONTHLY APPOINTMENT VOLUME TREND
C81: NO-SHOW RECOVERY PIPELINE MATRIX
C83: Target No-Show Reduction Goal | E83: Total No-Shows | G83: Saved Appointments | I83: Avg Session Fee | K83: Recovered Revenue Pipeline
C84: 0.02 | E84: {=SUMPRODUCT((SUBTOTAL(103,OFFSET(INDEX(Appointments_Tbl[Appointment_ID],1),ROW(Appointments_Tbl[Appointment_ID])-ROW(INDEX(Appointments_Tbl[Appointment_ID],1)),0,1)))*(Appointments_Tbl[No_Show_Flag]))} -> 302 | G84: =E84*C84 -> 6.04 | I84: {=IFERROR(SUMPRODUCT((SUBTOTAL(103,OFFSET(INDEX(Appointments_Tbl[Appointment_ID],1),ROW(Appointments_Tbl[Appointment_ID])-ROW(INDEX(Appointments_Tbl[Appointment_ID],1)),0,1)))*(Appointments_Tbl[No_Show_Flag])*(Appointments_Tbl[Session_Fee_INR]))/E84,0)} -> 1334.4371 | K84: =G84*I84 -> 8060
C87: Formula: Saved Appointments = Total No-Shows × Reduction Goal. Recovered Revenue Pipeline = Saved Appointments × Average Session Fee for visible no-show appointments.
